W&B disabled.
2023-10-13 16:30:20,492 MainThread INFO: Experiment Name:testing_must_mtsac
2023-10-13 16:30:20,493 MainThread INFO: {
  "env_name": "mt10",
  "env": {
    "reward_scale": 1,
    "obs_norm": false
  },
  "meta_env": {
    "obs_type": "with_goal_and_id"
  },
  "replay_buffer": {
    "size": 1000000.0
  },
  "net": {
    "hidden_shapes": [
      40,
      40,
      40
    ]
  },
  "task_embedding": {
    "em_hidden_shapes": [
      20,
      20,
      20
    ]
  },
  "traj_encoder": {
    "latent_size": 256
  },
  "sparse_training": {
    "pruning_ratio": 0.4
  },
  "general_setting": {
    "discount": 0.99,
    "pretrain_epochs": 0,
    "num_epochs": 1000,
    "epoch_frames": 150,
    "max_episode_frames": 150,
    "generator_lr": 0.0001,
    "batch_size": 1280,
    "min_pool": 10000,
    "success_traj_update_only": true,
    "target_hard_update_period": 1000,
    "use_soft_update": true,
    "tau": 0.005,
    "opt_times": 200,
    "update_end_epoch": 1000,
    "mask_update_interval": 25,
    "eval_episodes": 3,
    "recent_traj_window": 10,
    "sl_optim_times": 5,
    "use_trajectory_info": 0
  },
  "sac": {
    "plr": 0.0003,
    "qlr": 0.0003,
    "reparameterization": true,
    "automatic_entropy_tuning": true,
    "policy_std_reg_weight": 0,
    "policy_mean_reg_weight": 0
  }
}
finish policy net init
mask generator finish initialization
/lustre04/scratch/qianxi/sparse_training/sep_t3s/venv/lib/python3.8/site-packages/gym/logger.py:30: UserWarning: [33mWARN: Could not seed environment <MTEnv instance>[0m
  warnings.warn(colorize('%s: %s'%('WARN', msg % args), 'yellow'))
wandb: Tracking run with wandb version 0.15.5
wandb: W&B syncing is set to `offline` in this directory.  
wandb: Run `wandb online` or set WANDB_MODE=online to enable cloud syncing.
2023-10-13 16:31:26,293 MainThread INFO: Finished Pretrain
  0%|          | 0/1000 [00:00<?, ?it/s]/lustre04/scratch/qianxi/sparse_training/sep_t3s/DST_RL/./torchrl/algo/rl_algo.py:385: UserWarning: This overload of nonzero is deprecated:
	nonzero()
Consider using one of the following signatures instead:
	nonzero(*, bool as_tuple) (Triggered internally at  /pytorch/torch/csrc/utils/python_arg_parser.cpp:882.)
  value = torch.sum((self.mask_buffer["Policy"][each_task][0] == 0).nonzero().squeeze()).item()
  0%|          | 0/1000 [00:00<?, ?it/s]
sample: [9, 5, 3, 2, 8, 0, 6, 1, 7, 4]
replay_buffer._size: [300 300 300 300 300 300 300 300 300 300]
[torch.Size([10, 40, 19]), torch.Size([10, 40]), torch.Size([10, 40, 40]), torch.Size([10, 40]), torch.Size([10, 40, 40]), torch.Size([10, 40]), torch.Size([10, 8, 40]), torch.Size([10, 8])]
wandb: Waiting for W&B process to finish... (failed 1).
wandb: 
wandb: Run history:
wandb:  save_traj_mod_sum ▁
wandb: task_policy_mask_0 ▁
wandb: task_policy_mask_1 ▁
wandb: task_policy_mask_2 ▁
wandb: task_policy_mask_3 ▁
wandb: task_policy_mask_4 ▁
wandb: task_policy_mask_5 ▁
wandb: task_policy_mask_6 ▁
wandb: task_policy_mask_7 ▁
wandb: task_policy_mask_8 ▁
wandb: task_policy_mask_9 ▁
wandb: 
wandb: Run summary:
wandb:  save_traj_mod_sum 0
wandb: task_policy_mask_0 8809
wandb: task_policy_mask_1 8502
wandb: task_policy_mask_2 8574
wandb: task_policy_mask_3 8852
wandb: task_policy_mask_4 8787
wandb: task_policy_mask_5 9140
wandb: task_policy_mask_6 8869
wandb: task_policy_mask_7 8487
wandb: task_policy_mask_8 8535
wandb: task_policy_mask_9 8437
wandb: 
wandb: You can sync this run to the cloud by running:
wandb: wandb sync /lustre04/scratch/qianxi/sparse_training/sep_t3s/DST_RL/wandb/offline-run-20231013_163124-e3xh4sub
wandb: Find logs at: ./wandb/offline-run-20231013_163124-e3xh4sub/logs
Process Process-20:
Traceback (most recent call last):
  File "/cvmfs/soft.computecanada.ca/easybuild/software/2020/avx512/Core/python/3.8.10/lib/python3.8/multiprocessing/managers.py", line 827, in _callmethod
    conn = self._tls.connection
AttributeError: 'ForkAwareLocal' object has no attribute 'connection'

During handling of the above exception, another exception occurred:

Traceback (most recent call last):
  File "/cvmfs/soft.computecanada.ca/easybuild/software/2020/avx512/Core/python/3.8.10/lib/python3.8/multiprocessing/process.py", line 315, in _bootstrap
    self.run()
  File "/cvmfs/soft.computecanada.ca/easybuild/software/2020/avx512/Core/python/3.8.10/lib/python3.8/multiprocessing/process.py", line 108, in run
    self._target(*self._args, **self._kwargs)
  File "/lustre04/scratch/qianxi/sparse_training/sep_t3s/DST_RL/./torchrl/collector/para/async_mt.py", line 365, in eval_worker_process
    mask_this_task = mask_buffer[env_info.env_rank]
  File "<string>", line 2, in __getitem__
  File "/cvmfs/soft.computecanada.ca/easybuild/software/2020/avx512/Core/python/3.8.10/lib/python3.8/multiprocessing/managers.py", line 831, in _callmethod
    self._connect()
  File "/cvmfs/soft.computecanada.ca/easybuild/software/2020/avx512/Core/python/3.8.10/lib/python3.8/multiprocessing/managers.py", line 818, in _connect
    conn = self._Client(self._token.address, authkey=self._authkey)
  File "/cvmfs/soft.computecanada.ca/easybuild/software/2020/avx512/Core/python/3.8.10/lib/python3.8/multiprocessing/connection.py", line 502, in Client
    c = SocketClient(address)
  File "/cvmfs/soft.computecanada.ca/easybuild/software/2020/avx512/Core/python/3.8.10/lib/python3.8/multiprocessing/connection.py", line 630, in SocketClient
    s.connect(address)
FileNotFoundError: [Errno 2] No such file or directory
Process Process-12:
Traceback (most recent call last):
  File "/cvmfs/soft.computecanada.ca/easybuild/software/2020/avx512/Core/python/3.8.10/lib/python3.8/multiprocessing/managers.py", line 827, in _callmethod
    conn = self._tls.connection
AttributeError: 'ForkAwareLocal' object has no attribute 'connection'

During handling of the above exception, another exception occurred:

Traceback (most recent call last):
  File "/cvmfs/soft.computecanada.ca/easybuild/software/2020/avx512/Core/python/3.8.10/lib/python3.8/multiprocessing/process.py", line 315, in _bootstrap
    self.run()
  File "/cvmfs/soft.computecanada.ca/easybuild/software/2020/avx512/Core/python/3.8.10/lib/python3.8/multiprocessing/process.py", line 108, in run
    self._target(*self._args, **self._kwargs)
  File "/lustre04/scratch/qianxi/sparse_training/sep_t3s/DST_RL/./torchrl/collector/para/async_mt.py", line 365, in eval_worker_process
    mask_this_task = mask_buffer[env_info.env_rank]
  File "<string>", line 2, in __getitem__
  File "/cvmfs/soft.computecanada.ca/easybuild/software/2020/avx512/Core/python/3.8.10/lib/python3.8/multiprocessing/managers.py", line 831, in _callmethod
    self._connect()
  File "/cvmfs/soft.computecanada.ca/easybuild/software/2020/avx512/Core/python/3.8.10/lib/python3.8/multiprocessing/managers.py", line 818, in _connect
    conn = self._Client(self._token.address, authkey=self._authkey)
  File "/cvmfs/soft.computecanada.ca/easybuild/software/2020/avx512/Core/python/3.8.10/lib/python3.8/multiprocessing/connection.py", line 502, in Client
    c = SocketClient(address)
  File "/cvmfs/soft.computecanada.ca/easybuild/software/2020/avx512/Core/python/3.8.10/lib/python3.8/multiprocessing/connection.py", line 630, in SocketClient
    s.connect(address)
FileNotFoundError: [Errno 2] No such file or directory
Process Process-19:
Traceback (most recent call last):
  File "/cvmfs/soft.computecanada.ca/easybuild/software/2020/avx512/Core/python/3.8.10/lib/python3.8/multiprocessing/managers.py", line 827, in _callmethod
    conn = self._tls.connection
AttributeError: 'ForkAwareLocal' object has no attribute 'connection'

During handling of the above exception, another exception occurred:

Traceback (most recent call last):
  File "/cvmfs/soft.computecanada.ca/easybuild/software/2020/avx512/Core/python/3.8.10/lib/python3.8/multiprocessing/process.py", line 315, in _bootstrap
    self.run()
  File "/cvmfs/soft.computecanada.ca/easybuild/software/2020/avx512/Core/python/3.8.10/lib/python3.8/multiprocessing/process.py", line 108, in run
    self._target(*self._args, **self._kwargs)
  File "/lustre04/scratch/qianxi/sparse_training/sep_t3s/DST_RL/./torchrl/collector/para/async_mt.py", line 365, in eval_worker_process
    mask_this_task = mask_buffer[env_info.env_rank]
  File "<string>", line 2, in __getitem__
  File "/cvmfs/soft.computecanada.ca/easybuild/software/2020/avx512/Core/python/3.8.10/lib/python3.8/multiprocessing/managers.py", line 831, in _callmethod
    self._connect()
  File "/cvmfs/soft.computecanada.ca/easybuild/software/2020/avx512/Core/python/3.8.10/lib/python3.8/multiprocessing/managers.py", line 818, in _connect
    conn = self._Client(self._token.address, authkey=self._authkey)
  File "/cvmfs/soft.computecanada.ca/easybuild/software/2020/avx512/Core/python/3.8.10/lib/python3.8/multiprocessing/connection.py", line 502, in Client
    c = SocketClient(address)
  File "/cvmfs/soft.computecanada.ca/easybuild/software/2020/avx512/Core/python/3.8.10/lib/python3.8/multiprocessing/connection.py", line 630, in SocketClient
    s.connect(address)
FileNotFoundError: [Errno 2] No such file or directory
Process Process-15:
Traceback (most recent call last):
  File "/cvmfs/soft.computecanada.ca/easybuild/software/2020/avx512/Core/python/3.8.10/lib/python3.8/multiprocessing/managers.py", line 827, in _callmethod
    conn = self._tls.connection
AttributeError: 'ForkAwareLocal' object has no attribute 'connection'

During handling of the above exception, another exception occurred:

Traceback (most recent call last):
  File "/cvmfs/soft.computecanada.ca/easybuild/software/2020/avx512/Core/python/3.8.10/lib/python3.8/multiprocessing/process.py", line 315, in _bootstrap
    self.run()
  File "/cvmfs/soft.computecanada.ca/easybuild/software/2020/avx512/Core/python/3.8.10/lib/python3.8/multiprocessing/process.py", line 108, in run
    self._target(*self._args, **self._kwargs)
  File "/lustre04/scratch/qianxi/sparse_training/sep_t3s/DST_RL/./torchrl/collector/para/async_mt.py", line 365, in eval_worker_process
    mask_this_task = mask_buffer[env_info.env_rank]
  File "<string>", line 2, in __getitem__
  File "/cvmfs/soft.computecanada.ca/easybuild/software/2020/avx512/Core/python/3.8.10/lib/python3.8/multiprocessing/managers.py", line 831, in _callmethod
    self._connect()
  File "/cvmfs/soft.computecanada.ca/easybuild/software/2020/avx512/Core/python/3.8.10/lib/python3.8/multiprocessing/managers.py", line 818, in _connect
    conn = self._Client(self._token.address, authkey=self._authkey)
  File "/cvmfs/soft.computecanada.ca/easybuild/software/2020/avx512/Core/python/3.8.10/lib/python3.8/multiprocessing/connection.py", line 502, in Client
    c = SocketClient(address)
  File "/cvmfs/soft.computecanada.ca/easybuild/software/2020/avx512/Core/python/3.8.10/lib/python3.8/multiprocessing/connection.py", line 630, in SocketClient
    s.connect(address)
FileNotFoundError: [Errno 2] No such file or directory
Process Process-13:
Traceback (most recent call last):
  File "/cvmfs/soft.computecanada.ca/easybuild/software/2020/avx512/Core/python/3.8.10/lib/python3.8/multiprocessing/managers.py", line 827, in _callmethod
    conn = self._tls.connection
AttributeError: 'ForkAwareLocal' object has no attribute 'connection'

During handling of the above exception, another exception occurred:

Traceback (most recent call last):
  File "/cvmfs/soft.computecanada.ca/easybuild/software/2020/avx512/Core/python/3.8.10/lib/python3.8/multiprocessing/process.py", line 315, in _bootstrap
    self.run()
  File "/cvmfs/soft.computecanada.ca/easybuild/software/2020/avx512/Core/python/3.8.10/lib/python3.8/multiprocessing/process.py", line 108, in run
    self._target(*self._args, **self._kwargs)
  File "/lustre04/scratch/qianxi/sparse_training/sep_t3s/DST_RL/./torchrl/collector/para/async_mt.py", line 365, in eval_worker_process
    mask_this_task = mask_buffer[env_info.env_rank]
  File "<string>", line 2, in __getitem__
  File "/cvmfs/soft.computecanada.ca/easybuild/software/2020/avx512/Core/python/3.8.10/lib/python3.8/multiprocessing/managers.py", line 831, in _callmethod
    self._connect()
  File "/cvmfs/soft.computecanada.ca/easybuild/software/2020/avx512/Core/python/3.8.10/lib/python3.8/multiprocessing/managers.py", line 818, in _connect
    conn = self._Client(self._token.address, authkey=self._authkey)
  File "/cvmfs/soft.computecanada.ca/easybuild/software/2020/avx512/Core/python/3.8.10/lib/python3.8/multiprocessing/connection.py", line 502, in Client
    c = SocketClient(address)
  File "/cvmfs/soft.computecanada.ca/easybuild/software/2020/avx512/Core/python/3.8.10/lib/python3.8/multiprocessing/connection.py", line 630, in SocketClient
    s.connect(address)
FileNotFoundError: [Errno 2] No such file or directory
Process Process-21:
Traceback (most recent call last):
  File "/cvmfs/soft.computecanada.ca/easybuild/software/2020/avx512/Core/python/3.8.10/lib/python3.8/multiprocessing/managers.py", line 827, in _callmethod
    conn = self._tls.connection
AttributeError: 'ForkAwareLocal' object has no attribute 'connection'

During handling of the above exception, another exception occurred:

Traceback (most recent call last):
  File "/cvmfs/soft.computecanada.ca/easybuild/software/2020/avx512/Core/python/3.8.10/lib/python3.8/multiprocessing/process.py", line 315, in _bootstrap
    self.run()
  File "/cvmfs/soft.computecanada.ca/easybuild/software/2020/avx512/Core/python/3.8.10/lib/python3.8/multiprocessing/process.py", line 108, in run
    self._target(*self._args, **self._kwargs)
  File "/lustre04/scratch/qianxi/sparse_training/sep_t3s/DST_RL/./torchrl/collector/para/async_mt.py", line 365, in eval_worker_process
    mask_this_task = mask_buffer[env_info.env_rank]
  File "<string>", line 2, in __getitem__
  File "/cvmfs/soft.computecanada.ca/easybuild/software/2020/avx512/Core/python/3.8.10/lib/python3.8/multiprocessing/managers.py", line 831, in _callmethod
    self._connect()
  File "/cvmfs/soft.computecanada.ca/easybuild/software/2020/avx512/Core/python/3.8.10/lib/python3.8/multiprocessing/managers.py", line 818, in _connect
    conn = self._Client(self._token.address, authkey=self._authkey)
  File "/cvmfs/soft.computecanada.ca/easybuild/software/2020/avx512/Core/python/3.8.10/lib/python3.8/multiprocessing/connection.py", line 502, in Client
    c = SocketClient(address)
  File "/cvmfs/soft.computecanada.ca/easybuild/software/2020/avx512/Core/python/3.8.10/lib/python3.8/multiprocessing/connection.py", line 630, in SocketClient
    s.connect(address)
FileNotFoundError: [Errno 2] No such file or directory
Process Process-14:
Traceback (most recent call last):
  File "/cvmfs/soft.computecanada.ca/easybuild/software/2020/avx512/Core/python/3.8.10/lib/python3.8/multiprocessing/managers.py", line 827, in _callmethod
    conn = self._tls.connection
AttributeError: 'ForkAwareLocal' object has no attribute 'connection'

During handling of the above exception, another exception occurred:

Traceback (most recent call last):
  File "/cvmfs/soft.computecanada.ca/easybuild/software/2020/avx512/Core/python/3.8.10/lib/python3.8/multiprocessing/process.py", line 315, in _bootstrap
    self.run()
  File "/cvmfs/soft.computecanada.ca/easybuild/software/2020/avx512/Core/python/3.8.10/lib/python3.8/multiprocessing/process.py", line 108, in run
    self._target(*self._args, **self._kwargs)
  File "/lustre04/scratch/qianxi/sparse_training/sep_t3s/DST_RL/./torchrl/collector/para/async_mt.py", line 365, in eval_worker_process
    mask_this_task = mask_buffer[env_info.env_rank]
  File "<string>", line 2, in __getitem__
  File "/cvmfs/soft.computecanada.ca/easybuild/software/2020/avx512/Core/python/3.8.10/lib/python3.8/multiprocessing/managers.py", line 831, in _callmethod
    self._connect()
  File "/cvmfs/soft.computecanada.ca/easybuild/software/2020/avx512/Core/python/3.8.10/lib/python3.8/multiprocessing/managers.py", line 818, in _connect
    conn = self._Client(self._token.address, authkey=self._authkey)
  File "/cvmfs/soft.computecanada.ca/easybuild/software/2020/avx512/Core/python/3.8.10/lib/python3.8/multiprocessing/connection.py", line 502, in Client
    c = SocketClient(address)
  File "/cvmfs/soft.computecanada.ca/easybuild/software/2020/avx512/Core/python/3.8.10/lib/python3.8/multiprocessing/connection.py", line 630, in SocketClient
    s.connect(address)
FileNotFoundError: [Errno 2] No such file or directory
Process Process-16:
Traceback (most recent call last):
  File "/cvmfs/soft.computecanada.ca/easybuild/software/2020/avx512/Core/python/3.8.10/lib/python3.8/multiprocessing/managers.py", line 827, in _callmethod
    conn = self._tls.connection
AttributeError: 'ForkAwareLocal' object has no attribute 'connection'

During handling of the above exception, another exception occurred:

Traceback (most recent call last):
  File "/cvmfs/soft.computecanada.ca/easybuild/software/2020/avx512/Core/python/3.8.10/lib/python3.8/multiprocessing/process.py", line 315, in _bootstrap
    self.run()
  File "/cvmfs/soft.computecanada.ca/easybuild/software/2020/avx512/Core/python/3.8.10/lib/python3.8/multiprocessing/process.py", line 108, in run
    self._target(*self._args, **self._kwargs)
  File "/lustre04/scratch/qianxi/sparse_training/sep_t3s/DST_RL/./torchrl/collector/para/async_mt.py", line 365, in eval_worker_process
    mask_this_task = mask_buffer[env_info.env_rank]
  File "<string>", line 2, in __getitem__
  File "/cvmfs/soft.computecanada.ca/easybuild/software/2020/avx512/Core/python/3.8.10/lib/python3.8/multiprocessing/managers.py", line 831, in _callmethod
    self._connect()
  File "/cvmfs/soft.computecanada.ca/easybuild/software/2020/avx512/Core/python/3.8.10/lib/python3.8/multiprocessing/managers.py", line 818, in _connect
    conn = self._Client(self._token.address, authkey=self._authkey)
  File "/cvmfs/soft.computecanada.ca/easybuild/software/2020/avx512/Core/python/3.8.10/lib/python3.8/multiprocessing/connection.py", line 502, in Client
    c = SocketClient(address)
  File "/cvmfs/soft.computecanada.ca/easybuild/software/2020/avx512/Core/python/3.8.10/lib/python3.8/multiprocessing/connection.py", line 630, in SocketClient
    s.connect(address)
FileNotFoundError: [Errno 2] No such file or directory
Process Process-17:
Traceback (most recent call last):
  File "/cvmfs/soft.computecanada.ca/easybuild/software/2020/avx512/Core/python/3.8.10/lib/python3.8/multiprocessing/managers.py", line 827, in _callmethod
    conn = self._tls.connection
AttributeError: 'ForkAwareLocal' object has no attribute 'connection'

During handling of the above exception, another exception occurred:

Traceback (most recent call last):
  File "/cvmfs/soft.computecanada.ca/easybuild/software/2020/avx512/Core/python/3.8.10/lib/python3.8/multiprocessing/process.py", line 315, in _bootstrap
    self.run()
  File "/cvmfs/soft.computecanada.ca/easybuild/software/2020/avx512/Core/python/3.8.10/lib/python3.8/multiprocessing/process.py", line 108, in run
    self._target(*self._args, **self._kwargs)
  File "/lustre04/scratch/qianxi/sparse_training/sep_t3s/DST_RL/./torchrl/collector/para/async_mt.py", line 365, in eval_worker_process
    mask_this_task = mask_buffer[env_info.env_rank]
  File "<string>", line 2, in __getitem__
  File "/cvmfs/soft.computecanada.ca/easybuild/software/2020/avx512/Core/python/3.8.10/lib/python3.8/multiprocessing/managers.py", line 831, in _callmethod
    self._connect()
  File "/cvmfs/soft.computecanada.ca/easybuild/software/2020/avx512/Core/python/3.8.10/lib/python3.8/multiprocessing/managers.py", line 818, in _connect
    conn = self._Client(self._token.address, authkey=self._authkey)
  File "/cvmfs/soft.computecanada.ca/easybuild/software/2020/avx512/Core/python/3.8.10/lib/python3.8/multiprocessing/connection.py", line 502, in Client
    c = SocketClient(address)
  File "/cvmfs/soft.computecanada.ca/easybuild/software/2020/avx512/Core/python/3.8.10/lib/python3.8/multiprocessing/connection.py", line 630, in SocketClient
    s.connect(address)
FileNotFoundError: [Errno 2] No such file or directory
Process Process-18:
Traceback (most recent call last):
  File "/cvmfs/soft.computecanada.ca/easybuild/software/2020/avx512/Core/python/3.8.10/lib/python3.8/multiprocessing/managers.py", line 827, in _callmethod
    conn = self._tls.connection
AttributeError: 'ForkAwareLocal' object has no attribute 'connection'

During handling of the above exception, another exception occurred:

Traceback (most recent call last):
  File "/cvmfs/soft.computecanada.ca/easybuild/software/2020/avx512/Core/python/3.8.10/lib/python3.8/multiprocessing/process.py", line 315, in _bootstrap
    self.run()
  File "/cvmfs/soft.computecanada.ca/easybuild/software/2020/avx512/Core/python/3.8.10/lib/python3.8/multiprocessing/process.py", line 108, in run
    self._target(*self._args, **self._kwargs)
  File "/lustre04/scratch/qianxi/sparse_training/sep_t3s/DST_RL/./torchrl/collector/para/async_mt.py", line 365, in eval_worker_process
    mask_this_task = mask_buffer[env_info.env_rank]
  File "<string>", line 2, in __getitem__
  File "/cvmfs/soft.computecanada.ca/easybuild/software/2020/avx512/Core/python/3.8.10/lib/python3.8/multiprocessing/managers.py", line 831, in _callmethod
    self._connect()
  File "/cvmfs/soft.computecanada.ca/easybuild/software/2020/avx512/Core/python/3.8.10/lib/python3.8/multiprocessing/managers.py", line 818, in _connect
    conn = self._Client(self._token.address, authkey=self._authkey)
  File "/cvmfs/soft.computecanada.ca/easybuild/software/2020/avx512/Core/python/3.8.10/lib/python3.8/multiprocessing/connection.py", line 502, in Client
    c = SocketClient(address)
  File "/cvmfs/soft.computecanada.ca/easybuild/software/2020/avx512/Core/python/3.8.10/lib/python3.8/multiprocessing/connection.py", line 630, in SocketClient
    s.connect(address)
FileNotFoundError: [Errno 2] No such file or directory
Process Process-2:
Traceback (most recent call last):
  File "/cvmfs/soft.computecanada.ca/easybuild/software/2020/avx512/Core/python/3.8.10/lib/python3.8/multiprocessing/process.py", line 315, in _bootstrap
    self.run()
  File "/cvmfs/soft.computecanada.ca/easybuild/software/2020/avx512/Core/python/3.8.10/lib/python3.8/multiprocessing/process.py", line 108, in run
    self._target(*self._args, **self._kwargs)
  File "/lustre04/scratch/qianxi/sparse_training/sep_t3s/DST_RL/./torchrl/collector/para/async_mt.py", line 323, in train_worker_process
    shared_que.put({
  File "<string>", line 2, in put
  File "/cvmfs/soft.computecanada.ca/easybuild/software/2020/avx512/Core/python/3.8.10/lib/python3.8/multiprocessing/managers.py", line 835, in _callmethod
    kind, result = conn.recv()
  File "/cvmfs/soft.computecanada.ca/easybuild/software/2020/avx512/Core/python/3.8.10/lib/python3.8/multiprocessing/connection.py", line 250, in recv
    buf = self._recv_bytes()
  File "/cvmfs/soft.computecanada.ca/easybuild/software/2020/avx512/Core/python/3.8.10/lib/python3.8/multiprocessing/connection.py", line 414, in _recv_bytes
    buf = self._recv(4)
  File "/cvmfs/soft.computecanada.ca/easybuild/software/2020/avx512/Core/python/3.8.10/lib/python3.8/multiprocessing/connection.py", line 383, in _recv
    raise EOFError
EOFError
Process Process-11:
Traceback (most recent call last):
  File "/cvmfs/soft.computecanada.ca/easybuild/software/2020/avx512/Core/python/3.8.10/lib/python3.8/multiprocessing/process.py", line 315, in _bootstrap
    self.run()
  File "/cvmfs/soft.computecanada.ca/easybuild/software/2020/avx512/Core/python/3.8.10/lib/python3.8/multiprocessing/process.py", line 108, in run
    self._target(*self._args, **self._kwargs)
  File "/lustre04/scratch/qianxi/sparse_training/sep_t3s/DST_RL/./torchrl/collector/para/async_mt.py", line 323, in train_worker_process
    shared_que.put({
  File "<string>", line 2, in put
  File "/cvmfs/soft.computecanada.ca/easybuild/software/2020/avx512/Core/python/3.8.10/lib/python3.8/multiprocessing/managers.py", line 835, in _callmethod
    kind, result = conn.recv()
  File "/cvmfs/soft.computecanada.ca/easybuild/software/2020/avx512/Core/python/3.8.10/lib/python3.8/multiprocessing/connection.py", line 250, in recv
    buf = self._recv_bytes()
  File "/cvmfs/soft.computecanada.ca/easybuild/software/2020/avx512/Core/python/3.8.10/lib/python3.8/multiprocessing/connection.py", line 414, in _recv_bytes
    buf = self._recv(4)
  File "/cvmfs/soft.computecanada.ca/easybuild/software/2020/avx512/Core/python/3.8.10/lib/python3.8/multiprocessing/connection.py", line 383, in _recv
    raise EOFError
EOFError
Process Process-10:
Traceback (most recent call last):
  File "/cvmfs/soft.computecanada.ca/easybuild/software/2020/avx512/Core/python/3.8.10/lib/python3.8/multiprocessing/process.py", line 315, in _bootstrap
    self.run()
  File "/cvmfs/soft.computecanada.ca/easybuild/software/2020/avx512/Core/python/3.8.10/lib/python3.8/multiprocessing/process.py", line 108, in run
    self._target(*self._args, **self._kwargs)
  File "/lustre04/scratch/qianxi/sparse_training/sep_t3s/DST_RL/./torchrl/collector/para/async_mt.py", line 323, in train_worker_process
    shared_que.put({
  File "<string>", line 2, in put
  File "/cvmfs/soft.computecanada.ca/easybuild/software/2020/avx512/Core/python/3.8.10/lib/python3.8/multiprocessing/managers.py", line 835, in _callmethod
    kind, result = conn.recv()
  File "/cvmfs/soft.computecanada.ca/easybuild/software/2020/avx512/Core/python/3.8.10/lib/python3.8/multiprocessing/connection.py", line 250, in recv
    buf = self._recv_bytes()
  File "/cvmfs/soft.computecanada.ca/easybuild/software/2020/avx512/Core/python/3.8.10/lib/python3.8/multiprocessing/connection.py", line 414, in _recv_bytes
    buf = self._recv(4)
  File "/cvmfs/soft.computecanada.ca/easybuild/software/2020/avx512/Core/python/3.8.10/lib/python3.8/multiprocessing/connection.py", line 383, in _recv
    raise EOFError
EOFError
Process Process-6:
Traceback (most recent call last):
  File "/cvmfs/soft.computecanada.ca/easybuild/software/2020/avx512/Core/python/3.8.10/lib/python3.8/multiprocessing/process.py", line 315, in _bootstrap
    self.run()
  File "/cvmfs/soft.computecanada.ca/easybuild/software/2020/avx512/Core/python/3.8.10/lib/python3.8/multiprocessing/process.py", line 108, in run
    self._target(*self._args, **self._kwargs)
  File "/lustre04/scratch/qianxi/sparse_training/sep_t3s/DST_RL/./torchrl/collector/para/async_mt.py", line 323, in train_worker_process
    shared_que.put({
  File "<string>", line 2, in put
  File "/cvmfs/soft.computecanada.ca/easybuild/software/2020/avx512/Core/python/3.8.10/lib/python3.8/multiprocessing/managers.py", line 835, in _callmethod
    kind, result = conn.recv()
  File "/cvmfs/soft.computecanada.ca/easybuild/software/2020/avx512/Core/python/3.8.10/lib/python3.8/multiprocessing/connection.py", line 250, in recv
    buf = self._recv_bytes()
  File "/cvmfs/soft.computecanada.ca/easybuild/software/2020/avx512/Core/python/3.8.10/lib/python3.8/multiprocessing/connection.py", line 414, in _recv_bytes
    buf = self._recv(4)
  File "/cvmfs/soft.computecanada.ca/easybuild/software/2020/avx512/Core/python/3.8.10/lib/python3.8/multiprocessing/connection.py", line 383, in _recv
    raise EOFError
EOFError
Process Process-8:
Traceback (most recent call last):
  File "/cvmfs/soft.computecanada.ca/easybuild/software/2020/avx512/Core/python/3.8.10/lib/python3.8/multiprocessing/process.py", line 315, in _bootstrap
    self.run()
  File "/cvmfs/soft.computecanada.ca/easybuild/software/2020/avx512/Core/python/3.8.10/lib/python3.8/multiprocessing/process.py", line 108, in run
    self._target(*self._args, **self._kwargs)
  File "/lustre04/scratch/qianxi/sparse_training/sep_t3s/DST_RL/./torchrl/collector/para/async_mt.py", line 323, in train_worker_process
    shared_que.put({
  File "<string>", line 2, in put
  File "/cvmfs/soft.computecanada.ca/easybuild/software/2020/avx512/Core/python/3.8.10/lib/python3.8/multiprocessing/managers.py", line 835, in _callmethod
    kind, result = conn.recv()
  File "/cvmfs/soft.computecanada.ca/easybuild/software/2020/avx512/Core/python/3.8.10/lib/python3.8/multiprocessing/connection.py", line 250, in recv
    buf = self._recv_bytes()
  File "/cvmfs/soft.computecanada.ca/easybuild/software/2020/avx512/Core/python/3.8.10/lib/python3.8/multiprocessing/connection.py", line 414, in _recv_bytes
    buf = self._recv(4)
  File "/cvmfs/soft.computecanada.ca/easybuild/software/2020/avx512/Core/python/3.8.10/lib/python3.8/multiprocessing/connection.py", line 383, in _recv
    raise EOFError
EOFError
Process Process-5:
Traceback (most recent call last):
  File "/cvmfs/soft.computecanada.ca/easybuild/software/2020/avx512/Core/python/3.8.10/lib/python3.8/multiprocessing/process.py", line 315, in _bootstrap
    self.run()
  File "/cvmfs/soft.computecanada.ca/easybuild/software/2020/avx512/Core/python/3.8.10/lib/python3.8/multiprocessing/process.py", line 108, in run
    self._target(*self._args, **self._kwargs)
  File "/lustre04/scratch/qianxi/sparse_training/sep_t3s/DST_RL/./torchrl/collector/para/async_mt.py", line 323, in train_worker_process
    shared_que.put({
  File "<string>", line 2, in put
  File "/cvmfs/soft.computecanada.ca/easybuild/software/2020/avx512/Core/python/3.8.10/lib/python3.8/multiprocessing/managers.py", line 835, in _callmethod
    kind, result = conn.recv()
  File "/cvmfs/soft.computecanada.ca/easybuild/software/2020/avx512/Core/python/3.8.10/lib/python3.8/multiprocessing/connection.py", line 250, in recv
    buf = self._recv_bytes()
  File "/cvmfs/soft.computecanada.ca/easybuild/software/2020/avx512/Core/python/3.8.10/lib/python3.8/multiprocessing/connection.py", line 414, in _recv_bytes
    buf = self._recv(4)
  File "/cvmfs/soft.computecanada.ca/easybuild/software/2020/avx512/Core/python/3.8.10/lib/python3.8/multiprocessing/connection.py", line 383, in _recv
    raise EOFError
EOFError
Process Process-9:
Traceback (most recent call last):
  File "/cvmfs/soft.computecanada.ca/easybuild/software/2020/avx512/Core/python/3.8.10/lib/python3.8/multiprocessing/process.py", line 315, in _bootstrap
    self.run()
  File "/cvmfs/soft.computecanada.ca/easybuild/software/2020/avx512/Core/python/3.8.10/lib/python3.8/multiprocessing/process.py", line 108, in run
    self._target(*self._args, **self._kwargs)
  File "/lustre04/scratch/qianxi/sparse_training/sep_t3s/DST_RL/./torchrl/collector/para/async_mt.py", line 323, in train_worker_process
    shared_que.put({
  File "<string>", line 2, in put
  File "/cvmfs/soft.computecanada.ca/easybuild/software/2020/avx512/Core/python/3.8.10/lib/python3.8/multiprocessing/managers.py", line 835, in _callmethod
    kind, result = conn.recv()
  File "/cvmfs/soft.computecanada.ca/easybuild/software/2020/avx512/Core/python/3.8.10/lib/python3.8/multiprocessing/connection.py", line 250, in recv
    buf = self._recv_bytes()
  File "/cvmfs/soft.computecanada.ca/easybuild/software/2020/avx512/Core/python/3.8.10/lib/python3.8/multiprocessing/connection.py", line 414, in _recv_bytes
    buf = self._recv(4)
  File "/cvmfs/soft.computecanada.ca/easybuild/software/2020/avx512/Core/python/3.8.10/lib/python3.8/multiprocessing/connection.py", line 383, in _recv
    raise EOFError
EOFError
Process Process-3:
Traceback (most recent call last):
  File "/cvmfs/soft.computecanada.ca/easybuild/software/2020/avx512/Core/python/3.8.10/lib/python3.8/multiprocessing/process.py", line 315, in _bootstrap
    self.run()
  File "/cvmfs/soft.computecanada.ca/easybuild/software/2020/avx512/Core/python/3.8.10/lib/python3.8/multiprocessing/process.py", line 108, in run
    self._target(*self._args, **self._kwargs)
  File "/lustre04/scratch/qianxi/sparse_training/sep_t3s/DST_RL/./torchrl/collector/para/async_mt.py", line 323, in train_worker_process
    shared_que.put({
  File "<string>", line 2, in put
  File "/cvmfs/soft.computecanada.ca/easybuild/software/2020/avx512/Core/python/3.8.10/lib/python3.8/multiprocessing/managers.py", line 835, in _callmethod
    kind, result = conn.recv()
  File "/cvmfs/soft.computecanada.ca/easybuild/software/2020/avx512/Core/python/3.8.10/lib/python3.8/multiprocessing/connection.py", line 250, in recv
    buf = self._recv_bytes()
  File "/cvmfs/soft.computecanada.ca/easybuild/software/2020/avx512/Core/python/3.8.10/lib/python3.8/multiprocessing/connection.py", line 414, in _recv_bytes
    buf = self._recv(4)
  File "/cvmfs/soft.computecanada.ca/easybuild/software/2020/avx512/Core/python/3.8.10/lib/python3.8/multiprocessing/connection.py", line 383, in _recv
    raise EOFError
EOFError
Process Process-7:
Traceback (most recent call last):
  File "/cvmfs/soft.computecanada.ca/easybuild/software/2020/avx512/Core/python/3.8.10/lib/python3.8/multiprocessing/process.py", line 315, in _bootstrap
    self.run()
  File "/cvmfs/soft.computecanada.ca/easybuild/software/2020/avx512/Core/python/3.8.10/lib/python3.8/multiprocessing/process.py", line 108, in run
    self._target(*self._args, **self._kwargs)
  File "/lustre04/scratch/qianxi/sparse_training/sep_t3s/DST_RL/./torchrl/collector/para/async_mt.py", line 323, in train_worker_process
    shared_que.put({
  File "<string>", line 2, in put
  File "/cvmfs/soft.computecanada.ca/easybuild/software/2020/avx512/Core/python/3.8.10/lib/python3.8/multiprocessing/managers.py", line 835, in _callmethod
    kind, result = conn.recv()
  File "/cvmfs/soft.computecanada.ca/easybuild/software/2020/avx512/Core/python/3.8.10/lib/python3.8/multiprocessing/connection.py", line 250, in recv
    buf = self._recv_bytes()
  File "/cvmfs/soft.computecanada.ca/easybuild/software/2020/avx512/Core/python/3.8.10/lib/python3.8/multiprocessing/connection.py", line 414, in _recv_bytes
    buf = self._recv(4)
  File "/cvmfs/soft.computecanada.ca/easybuild/software/2020/avx512/Core/python/3.8.10/lib/python3.8/multiprocessing/connection.py", line 383, in _recv
    raise EOFError
EOFError
Process Process-4:
Traceback (most recent call last):
  File "/cvmfs/soft.computecanada.ca/easybuild/software/2020/avx512/Core/python/3.8.10/lib/python3.8/multiprocessing/process.py", line 315, in _bootstrap
    self.run()
  File "/cvmfs/soft.computecanada.ca/easybuild/software/2020/avx512/Core/python/3.8.10/lib/python3.8/multiprocessing/process.py", line 108, in run
    self._target(*self._args, **self._kwargs)
  File "/lustre04/scratch/qianxi/sparse_training/sep_t3s/DST_RL/./torchrl/collector/para/async_mt.py", line 323, in train_worker_process
    shared_que.put({
  File "<string>", line 2, in put
  File "/cvmfs/soft.computecanada.ca/easybuild/software/2020/avx512/Core/python/3.8.10/lib/python3.8/multiprocessing/managers.py", line 835, in _callmethod
    kind, result = conn.recv()
  File "/cvmfs/soft.computecanada.ca/easybuild/software/2020/avx512/Core/python/3.8.10/lib/python3.8/multiprocessing/connection.py", line 250, in recv
    buf = self._recv_bytes()
  File "/cvmfs/soft.computecanada.ca/easybuild/software/2020/avx512/Core/python/3.8.10/lib/python3.8/multiprocessing/connection.py", line 414, in _recv_bytes
    buf = self._recv(4)
  File "/cvmfs/soft.computecanada.ca/easybuild/software/2020/avx512/Core/python/3.8.10/lib/python3.8/multiprocessing/connection.py", line 383, in _recv
    raise EOFError
EOFError
Traceback (most recent call last):
  File "starter/mt_must_sac.py", line 346, in <module>
    experiment(args)
  File "starter/mt_must_sac.py", line 341, in experiment
    agent.train(env.num_tasks,params,group_name)
  File "/lustre04/scratch/qianxi/sparse_training/sep_t3s/DST_RL/./torchrl/algo/rl_algo.py", line 427, in train
    self.update_per_epoch(task_sample_index, task_scheduler, self.mask_buffer, epoch,self.use_trajectory_info)
  File "/lustre04/scratch/qianxi/sparse_training/sep_t3s/DST_RL/./torchrl/algo/off_policy/must_sac.py", line 399, in update_per_epoch
    mask_buffer_copy = self.get_masks(self.task_nums,self.task_nums, epoch,use_trajectory_info)
  File "/lustre04/scratch/qianxi/sparse_training/sep_t3s/DST_RL/./torchrl/algo/off_policy/must_sac.py", line 82, in get_masks
    _,batch_task_binary_masks = generator(task_traj_batch, task_onehot_batch)
  File "/lustre04/scratch/qianxi/sparse_training/sep_t3s/venv/lib/python3.8/site-packages/torch/nn/modules/module.py", line 727, in _call_impl
    result = self.forward(*input, **kwargs)
  File "/lustre04/scratch/qianxi/sparse_training/sep_t3s/DST_RL/./torchrl/networks/nets.py", line 483, in forward
    return torch.cat(task_binary_masks,dim=1),converted_list
RuntimeError: Tensors must have same number of dimensions: got 3 and 2
95 seconds elapsed.
